Workbook

Sheet Cover
B3: KAMPALA UGANDA TEMPLE
B5: Master Information Delivery Plan
B7: The aggregated schedule of information deliverables for the project, compiled from the Task Information Delivery Plan of every appointed party.
B10: Document reference | C10: KUT-SMB-ZZ-ZZ-SH-Z-0001
B11: Revision | C11: P01
B12: Status / suitability | C12: DRAFT — not issued (S0, work in progress)
B13: Prepared by | C13: Symbion Consulting Group Studios (Information Manager)
B14: Baselined | C14: [FILL — date]
B15: Last updated | C15: [FILL — date]
B16: Update frequency | C16: Monthly, and at every data drop
B18: How to use this workbook
B19: Programme | C19: Enter the appointment date here, once. Every calendar date in the workbook is calculated from it.
B20: MIDP | C20: The project register. One row per deliverable. Filter by discipline, stage or status. The Information Manager maintains this sheet.
B21: TIDP-… | C21: One Task Information Delivery Plan per appointed party, pre-filled with the deliverables already assigned to it. Confirm the dates, add anything your scope requires that is not listed, and return the sheet. TIDP-ALL carries the deliverables every party owes.
B22: Summary | C22: Counts by stage, discipline and delivery plan, calculated from the MIDP sheet. Nothing is typed here.
B23: Drawing schedule | C23: Indicative sheet counts by volume and role, for production planning.
B24: Change log | C24: What changed since the previous issue of this register, and why, including the references that were retired.
B25: Lists | C25: The permitted values behind the drop-down lists. Amend here to change the drop-downs.
B27: Before this plan is baselined
B28: The Originator column is deliberately empty. The LENGTH is settled -- exactly three characters, which the compliance check enforces -- but the register that ALLOCATES a code to each appointed party has not been issued, so no row can state one. Complete this column only once the register is issued. Nothing on this project is to be numbered before that point. Symbion’s own containers already carry SMB in their document references, and the Information Manager rows could be completed on that basis if the Lead Appointed Party confirms SMB is its allocated code rather than a worked example.
B32: Not yet issued through the Common Data Environment. Uncontrolled when printed.
B34: Sheets in this workbook
B35: Programme
B36: MIDP
B37: TIDP-Z
B38: TIDP-A
B39: TIDP-S
B40: TIDP-M
B41: TIDP-E
B42: TIDP-P
... B53: Lists

Sheet Programme
A1: < Cover
B2: Programme
B4: Appointment date (M0) | E4: ← the only date entered by hand. Everything else is calculated from it.
B6: Stage durations are the Appointing Party Work Program: Phase 2 totals 11 months and Phase 3 totals 38 months, 49 in all, read in sequence.
B9: Stage | C9: From | D9: To | E9: Starts | F9: Ends | G9: Months
B10: 2.1 Basis of Design (Deliverable A) | C10: M1 | D10: M1 | E10: =IF($C4="","",EDATE($C4,0)) | F10: =IF($C4="","",EOMONTH($C4,0)) | G10: 1
B11: 2.2 Developed Design (Deliverable B) | C11: M2 | D11: M4 | E11: =IF($C4="","",EDATE($C4,1)) | F11: =IF($C4="","",EOMONTH($C4,3)) | G11: 3
B12: 2.3 Technical Design (Deliverable C) | C12: M5 | D12: M8 | E12: =IF($C4="","",EDATE($C4,4)) | F12: =IF($C4="","",EOMONTH($C4,7)) | G12: 4
B13: 2.4 Tender action, negotiation and award | C13: M9 | D13: M11 | E13: =IF($C4="","",EDATE($C4,8)) | F13: =IF($C4="","",EOMONTH($C4,10)) | G13: 3
B14: 2.5 Conformed set | C14: M11 | D14: M11 | E14: =IF($C4="","",EDATE($C4,10)) | F14: =IF($C4="","",EOMONTH($C4,10)) | G14: 0
B15: 3.1 Construction administration | C15: M12 | D15: M43 | E15: =IF($C4="","",EDATE($C4,11)) | F15: =IF($C4="","",EOMONTH($C4,42)) | G15: 32
B16: 3.2 FF&E installation | C16: M44 | D16: M47 | E16: =IF($C4="","",EDATE($C4,43)) | F16: =IF($C4="","",EOMONTH($C4,46)) | G16: 4
B17: 3.3 Close-out (Deliverable D) | C17: M48 | D17: M49 | E17: =IF($C4="","",EDATE($C4,47)) | F17: =IF($C4="","",EOMONTH($C4,48)) | G17: 2
B18: Total | G18: 49
B20: Calendar dates are indicative until the appointment date is entered and the plan is rebaselined. A stage runs to the end of its final month, so a stage ending M8 ends on the last day of the eighth month after appointment.

Sheet MIDP
A1: Ref | B1: Discipline | C1: Originator | D1: Volume | E1: Deliverable | F1: Type | G1: Type code | H1: Stage | I1: LOD | J1: Format | K1: Suitability | L1: CDE State | M1: Month from | N1: Month to | O1: Planned date | P1: Actual date | Q1: Variance (days) | R1: Responsible | S1: TIDP ref | T1: Critical | U1: As-built | V1: O&M | W1: RAG | X1: Notes
A2: Z-000 | B2: Information Management | D2: ZZ | E2: BIM Execution Plan | F2: Document | G2: RP | H2: Mobilisation | I2: n/a | J2: DOCX/PDF | K2: A1 | L2: Published | M2: 0 | N2: 0 | O2: =IF(Programme!$C$4="","",EOMONTH(Programme!$C$4,0)) | Q2: =IF(AND(O2<>"",P2<>""),P2-O2,"") | R2: Information Manager | S2: TIDP-Z | T2: N | U2: N | V2: N | X2: Baselined at mobilisation; reissued per stage
A3: Z-001 | B3: Information Management | D3: ZZ | E3: Master Information Delivery Plan | F3: Schedule | G3: SH | H3: Mobilisation | I3: n/a | J3: XLSX | K3: A1 | L3: Published | M3: 0 | N3: 0 | O3: =IF(Programme!$C$4="","",EOMONTH(Programme!$C$4,0)) | Q3: =IF(AND(O3<>"",P3<>""),P3-O3,"") | R3: Information Manager | S3: TIDP-Z | T3: N | U3: N | V3: N | X3: Aggregated from all TIDPs; monthly and per drop
A4: Z-002 | B4: Information Management | D4: ZZ | E4: Project Delivery Playbook | F4: Document | G4: RP | H4: Mobilisation | I4: n/a | J4: DOCX/PDF | K4: A1 | L4: Published | M4: 0 | N4: 0 | O4: =IF(Programme!$C$4="","",EOMONTH(Programme!$C$4,0)) | Q4: =IF(AND(O4<>"",P4<>""),P4-O4,"") | R4: Information Manager | S4: TIDP-Z | T4: N | U4: N | V4: N | X4: Reference RP-Z-0002
A5: Z-003 | B5: Information Management | D5: ZZ | E5: Responsibility matrix (RACI) | F5: Schedule | G5: SH | H5: Mobilisation | I5: n/a | J5: XLSX | K5: A1 | L5: Published | M5: 0 | N5: 0 | O5: =IF(Programme!$C$4="","",EOMONTH(Programme!$C$4,0)) | Q5: =IF(AND(O5<>"",P5<>""),P5-O5,"") | R5: Information Manager | S5: TIDP-Z | T5: N | U5: N | V5: N | X5: Reference SH-Z-0002
A6: Z-004 | B6: Information Management | D6: ZZ | E6: Project template, family library and title blocks | F6: Model | G6: M3 | H6: Mobilisation | I6: n/a | J6: RVT/RFA | K6: A1 | L6: Published | M6: 0 | N6: 0 | O6: =IF(Programme!$C$4="","",EOMONTH(Programme!$C$4,0)) | Q6: =IF(AND(O6<>"",P6<>""),P6-O6,"") | R6: Information Manager | S6: TIDP-Z | T6: Y | U6: N | V6: N | X6: Coordinates, levels, grids, worksets, shared parameters bound
A7: Z-005 | B7: Information Management | D7: ZZ | E7: Originator code register | F7: Schedule | G7: SH | H7: Mobilisation | I7: n/a | J7: XLSX | K7: A1 | L7: Published | M7: 0 | N7: 0 | O7: =IF(Programme!$C$4="","",EOMONTH(Programme!$C$4,0)) | Q7: =IF(AND(O7<>"",P7<>""),P7-O7,"") | R7: Lead Appointed Party | S7: TIDP-Z | T7: Y | U7: N | V7: N | X7: Required before any container is numbered; 3-character codes
A8: Z-006 | B8: All disciplines | D8: ZZ | E8: Task Information Delivery Plan (one per appointed party) | F8: Schedule | G8: SH | H8: Mobilisation | I8: n/a | J8: XLSX | K8: S3 | L8: Shared | M8: 0 | N8: 0 | O8: =IF(Programme!$C$4="","",EOMONTH(Programme!$C$4,0)) | Q8: =IF(AND(O8<>"",P8<>""),P8-O8,"") | R8: Task Team Managers | S8: TIDP-ALL | T8: N | U8: N | V8: N | X8: Returned to the Information Manager; merged into this MIDP
A9: Z-007 | B9: Information Management | D9: ZZ | E9: Standards reconciliation schedule (BEP 4.1.3) | F9: Schedule | G9: SH | H9: Mobilisation | I9: n/a | J9: XLSX/PDF | K9: S3 | L9: Shared | M9: 0 | N9: 8 | O9: =IF(Programme!$C$4="","",EOMONTH(Programme!$C$4,8)) | Q9: =IF(AND(O9<>"",P9<>""),P9-O9,"") | R9: All disciplines | S9: TIDP-Z | T9: Y | U9: N | V9: N | X9: Opened at mobilisation; closed before Stage 2.3
A10: Z-008 | B10: Information Management | D10: ZZ | E10: Shared coordinates seed model | F10: Model | G10: M3 | H10: Mobilisation | I10: n/a | J10: RVT | K10: A1 | L10: Published | M10: 0 | N10: 0 | O10: =IF(Programme!$C$4="","",EOMONTH(Programme!$C$4,0)) | Q10: =IF(AND(O10<>"",P10<>""),P10-O10,"") | R10: Information Manager | S10: TIDP-Z | T10: Y | U10: N | V10: N | X10: Survey point, project base point, true north, levels and grids
A11: Z-009 | B11: Information Management | D11: ZZ | E11: Level and grid register | F11: Schedule | G11: SH | H11: Mobilisation | I11: n/a | J11: XLSX/PDF | K11: A1 | L11: Published | M11: 0 | N11: 0 | O11: =IF(Programme!$C$4="","",EOMONTH(Programme!$C$4,0)) | Q11: =IF(AND(O11<>"",P11<>""),P11-O11,"") | R11: Lead Appointed Party | S11: TIDP-Z | T11: Y | U11: N | V11: N | X11: Reference SH-Z-0003
A12: Z-011 | B12: Information Management | D12: ZZ | E12: Software and version register | F12: Schedule | G12: SH | H12: Mobilisation | I12: n/a | J12: XLSX | K12: A1 | L12: Published | M12: 0 | N12: 0 | O12: =IF(Programme!$C$4="","",EOMONTH(Programme!$C$4,0)) | Q12: =IF(AND(O12<>"",P12<>""),P12-O12,"") | R12: All parties | S12: TIDP-Z | T12: N | U12: N | V12: N | X12: Revit 2025 locked project-wide
A13: Z-012 | B13: Information Management | D13: ZZ | E13: CDE folder structure and permission matrix | F13: Document | G13: RP | H13: Mobilisation | I13: n/a | J13: PDF | K13: A1 | L13: Published | M13: 0 | N13: 0 | O13: =IF(Programme!$C$4="","",EOMONTH(Programme!$C$4,0)) | Q13: =IF(AND(O13<>"",P13<>""),P13-O13,"") | R13: Information Manager | S13: TIDP-Z | T13: N | U13: N | V13: N | X13: ACC provisioned; seats confirmed for every party (E-01)
A14: Z-013 | B14: Information Management | D14: ZZ | E14: Information classification and access schedule | F14: Document | G14: RP | H14: Mobilisation | I14: n/a | J14: PDF | K14: A1 | L14: Published | M14: 0 | N14: 0 | O14: =IF(Programme!$C$4="","",EOMONTH(Programme!$C$4,0)) | Q14: =IF(AND(O14<>"",P14<>""),P14-O14,"") | R14: Appointing Party | S14: TIDP-Z | T14: Y | U14: N | V14: N | X14: Restricted spaces and systems classified before modelling begins
A15: Z-014 | B15: Information Management | D15: ZZ | E15: Clash matrix and tolerance schedule | F15: Document | G15: RP | H15: Mobilisation | I15: n/a | J15: PDF | K15: S3 | L15: Shared | M15: 1 | N15: 1 | O15: =IF(Programme!$C$4="","",EOMONTH(Programme!$C$4,1)) | Q15: =IF(AND(O15<>"",P15<>""),P15-O15,"") | R15: MEP and structural leads | S15: TIDP-Z | T15: Y | U15: N | V15: N | X15: Required before the first coordination cycle of Stage 2.2
A16: Z-015 | B16: Information Management | D16: ZZ | E16: IFC export configuration | F16: Document | G16: RP | H16: Mobilisation | I16: n/a | J16: PDF/JSON | K16: A1 | L16: Published | M16: 0 | N16: 0 | O16: =IF(Programme!$C$4="","",EOMONTH(Programme!$C$4,0)) | Q16: =IF(AND(O16<>"",P16<>""),P16-O16,"") | R16: Information Manager | S16: TIDP-Z | T16: N | U16: N | V16: N | X16: Issued centrally
A17: Z-016 | B17: Information Management | D17: ZZ | E17: Shared parameter file | F17: Document | G17: RP | H17: Mobilisation | I17: n/a | J17: TXT | K17: A1 | L17: Published | M17: 0 | N17: 0 | O17: =IF(Programme!$C$4="","",EOMONTH(Programme!$C$4,0)) | Q17: =IF(AND(O17<>"",P17<>""),P17-O17,"") | R17: Information Manager | S17: TIDP-Z | T17: Y | U17: N | V17: N | X17: Central ownership
A18: Z-017 | B18: Information Management | D18: ZZ | E18: Capability and capacity assessment | F18: Report | G18: RP | H18: Mobilisation | I18: n/a | J18: XLSX | K18: S3 | L18: Shared | M18: 1 | N18: 1 | O18: =IF(Programme!$C$4="","",EOMONTH(Programme!$C$4,1)) | Q18: =IF(AND(O18<>"",P18<>""),P18-O18,"") | R18: Lead Appointed Party | S18: TIDP-Z | T18: N | U18: N | V18: N | X18: ISO 19650-2; the Stage 0 test model is its practical form
A19: Z-018 | B19: Information Management | D19: ZZ | E19: Standards localisation note (Owner standards to Ugandan practice) | F19: Document | G19: RP | H19: Mobilisation | I19: n/a | J19: DOCX/PDF | K19: S3 | L19: Shared | M19: 0 | N19: 1 | O19: =IF(Programme!$C$4="","",EOMONTH(Programme!$C$4,1)) | Q19: =IF(AND(O19<>"",P19<>""),P19-O19,"") | R19: Information Manager | S19: TIDP-Z | T19: N | U19: N | V19: N | X19: Reference RP-Z-0005; weeks 2–3 after the Owner standards are received
A20: Z-019 | B20: Information Management | D20: ZZ | E20: Stage 0 gate record (test model shared by every appointed party) | F20: Report | G20: RP | H20: Mobilisation | I20: n/a | J20: PDF | K20: S3 | L20: Shared | M20: 1 | N20: 1 | O20: =IF(Programme!$C$4="","",EOMONTH(Programme!$C$4,1)) | Q20: =IF(AND(O20<>"",P20<>""),P20-O20,"") | R20: Information Manager | S20: TIDP-Z | T20: Y | U20: N | V20: N | X20: No discipline enters the fortnightly cycle before this
A21: Z-020 | B21: Information Management | D21: ZZ | E21: Monthly BIM status report (design stage) | F21: Report | G21: RP | H21: Mobilisation | I21: n/a | J21: PDF | K21: S2 | L21: Shared | M21: 1 | N21: 11 | O21: =IF(Programme!$C$4="","",EOMONTH(Programme!$C$4,11)) | Q21: =IF(AND(O21<>"",P21<>""),P21-O21,"") | R21: Information Manager | S21: TIDP-Z | T21: N | U21: N | V21: N | X21: KPIs per BEP 10.5
A22: Z-021 | B22: Information Management | D22: ZZ | E22: Kickoff induction record and BEP acknowledgement | F22: Document | G22: RP | H22: Mobilisation | I22: n/a | J22: PDF | K22: A1 | L22: Published | M22: 0 | N22: 1 | O22: =IF(Programme!$C$4="","",EOMONTH(Programme!$C$4,1)) | Q22: =IF(AND(O22<>"",P22<>""),P22-O22,"") | R22: Information Manager | S22: TIDP-Z | T22: N | U22: N | V22: N | X22: Attendance and signed acknowledgement from every task team
A23: Z-022 | B23: Information Management | D23: ZZ | E23: Document Control Standard (reissued to P02 codes) | F23: Document | G23: RP | H23: Mobilisation | I23: n/a | J23: DOCX/PDF | K23: A1 | L23: Published | M23: 0 | N23: 0 | O23: =IF(Programme!$C$4="","",EOMONTH(Programme!$C$4,0)) | Q23: =IF(AND(O23<>"",P23<>""),P23-O23,"") | R23: Information Manager | S23: TIDP-Z | T23: N | U23: N | V23: N | X23: KUT-SMB-ZZ-ZZ-RP-Z-0003. Container naming, sheet number bands, revision, authorisation, transmittal, superseded/cancelled/replaced notices, number retirement
A24: Z-024 | B24: Information Management | D24: ZZ | E24: Drawing register, transmittal and notice templates | F24: Document | G24: IE | H24: Mobilisation | I24: n/a | J24: XLSX/DOCX | K24: A1 | L24: Published | M24: 0 | N24: 0 | O24: =IF(Programme!$C$4="","",EOMONTH(Programme!$C$4,0)) | Q24: =IF(AND(O24<>"",P24<>""),P24-O24,"") | R24: Information Manager | S24: TIDP-Z | T24: N | U24: N | V24: N
A25: Z-010 | B25: Information Management | D25: ZZ | E25: Federated coordination model | F25: Model | G25: M3 | H25: 2.1 Deliverable A | I25: 200 | J25: NWC/NWD/IFC | K25: S1 | L25: Shared | M25: 1 | N25: 1 | O25: =IF(Programme!$C$4="","",EOMONTH(Programme!$C$4,1)) | Q25: =IF(AND(O25<>"",P25<>""),P25-O25,"") | R25: Information Manager | S25: TIDP-Z | T25: Y | U25: Y | V25: N | X25: First federation; container M3-Z-0001
A26: A-100 | B26: Architecture | D26: ZZ | E26: Architectural model | F26: Model | G26: M3 | H26: 2.1 Deliverable A | I26: 200 | J26: RVT/IFC | K26: S2 | L26: Shared | M26: 1 | N26: 1 | O26: =IF(Programme!$C$4="","",EOMONTH(Programme!$C$4,1)) | Q26: =IF(AND(O26<>"",P26<>""),P26-O26,"") | R26: Architecture lead | S26: TIDP-A | T26: Y | U26: Y | V26: N | X26: Massing and generic systems; rooms placed
A27: A-101 | B27: Architecture | D27: ZZ | E27: Deliverable A drawing set | F27: Drawing | G27: DR | H27: 2.1 Deliverable A | I27: 200 | J27: PDF/DWG | K27: S3 | L27: Shared | M27: 1 | N27: 1 | O27: =IF(Programme!$C$4="","",EOMONTH(Programme!$C$4,1)) | Q27: =IF(AND(O27<>"",P27<>""),P27-O27,"") | R27: Architecture lead | S27: TIDP-A | T27: N | U27: N | V27: N
A28: S-100 | B28: Structure | D28: ZZ | E28: Structural model | F28: Model | G28: M3 | H28: 2.1 Deliverable A | I28: 200 | J28: RVT/IFC | K28: S2 | L28: Shared | M28: 1 | N28: 1 | O28: =IF(Programme!$C$4="","",EOMONTH(Programme!$C$4,1)) | Q28: =IF(AND(O28<>"",P28<>""),P28-O28,"") | R28: Structural lead | S28: TIDP-S | T28: Y | U28: Y | V28: N | X28: Indicative frame and foundations
A29: M-100 | B29: Mechanical | D29: ZZ | E29: Mechanical model | F29: Model | G29: M3 | H29: 2.1 Deliverable A | I29: 200 | J29: RVT/IFC | K29: S2 | L29: Shared | M29: 1 | N29: 1 | O29: =IF(Programme!$C$4="","",EOMONTH(Programme!$C$4,1)) | Q29: =IF(AND(O29<>"",P29<>""),P29-O29,"") | R29: MEP lead | S29: TIDP-M | T29: Y | U29: Y | V29: N | X29: Plant space allocation, primary routes
A30: E-100 | B30: Electrical | D30: ZZ | E30: Electrical model | F30: Model | G30: M3 | H30: 2.1 Deliverable A | I30: 200 | J30: RVT/IFC | K30: S2 | L30: Shared | M30: 1 | N30: 1 | O30: =IF(Programme!$C$4="","",EOMONTH(Programme!$C$4,1)) | Q30: =IF(AND(O30<>"",P30<>""),P30-O30,"") | R30: MEP lead | S30: TIDP-E | T30: Y | U30: Y | V30: N | X30: Generic equipment and main containment
A31: P-100 | B31: Public Health | D31: ZZ | E31: Plumbing and drainage model | F31: Model | G31: M3 | H31: 2.1 Deliverable A | I31: 200 | J31: RVT/IFC | K31: S2 | L31: Shared | M31: 1 | N31: 1 | O31: =IF(Programme!$C$4="","",EOMONTH(Programme!$C$4,1)) | Q31: =IF(AND(O31<>"",P31<>""),P31-O31,"") | R31: MEP lead | S31: TIDP-P | T31: Y | U31: Y | V31: N | X31: Primary routes; font systems indicated
A32: G-100 | B32: Civil and Site | D32: 00 | E32: Site model and levels | F32: Model | G32: M3 | H32: 2.1 Deliverable A | I32: 200 | J32: RVT/IFC | K32: S2 | L32: Shared | M32: 1 | N32: 1 | O32: =IF(Programme!$C$4="","",EOMONTH(Programme!$C$4,1)) | Q32: =IF(AND(O32<>"",P32<>""),P32-O32,"") | R32: Civil lead | S32: TIDP-C | T32: Y | U32: Y | V32: N | X32: Site levels, access, drainage strategy; scope to confirm
A33: Z-110 | B33: Information Management | D33: ZZ | E33: Basis of design report | F33: Document | G33: RP | H33: 2.1 Deliverable A | I33: 200 | J33: DOCX/PDF | K33: S3 | L33: Shared | M33: 1 | N33: 1 | O33: =IF(Programme!$C$4="","",EOMONTH(Programme!$C$4,1)) | Q33: =IF(AND(O33<>"",P33<>""),P33-O33,"") | R33: Lead Appointed Party | S33: TIDP-Z | T33: N | U33: N | V33: N | X33: Design intent
A34: Z-111 | B34: Information Management | D34: ZZ | E34: Area schedule reconciled to the brief | F34: Schedule | G34: SH | H34: 2.1 Deliverable A | I34: 200 | J34: XLSX/PDF | K34: S3 | L34: Shared | M34: 1 | N34: 1 | O34: =IF(Programme!$C$4="","",EOMONTH(Programme!$C$4,1)) | Q34: =IF(AND(O34<>"",P34<>""),P34-O34,"") | R34: Information Manager | S34: TIDP-Z | T34: N | U34: N | V34: N | X34: Gate condition
A35: Z-112 | B35: Information Management | D35: ZZ | E35: Deliverable A gate pack and compliance report | F35: Document | G35: RP | H35: 2.1 Deliverable A | I35: 200 | J35: PDF | K35: S4 | L35: Shared | M35: 1 | N35: 1 | O35: =IF(Programme!$C$4="","",EOMONTH(Programme!$C$4,1)) | Q35: =IF(AND(O35<>"",P35<>""),P35-O35,"") | R35: Information Manager | S35: TIDP-Z | T35: Y | U35: N | V35: N | X35: Contents per Playbook Appendix B
A36: Z-113 | B36: Information Management | D36: ZZ | E36: Deliverable A Owner review set and comment close-out report | F36: Document | G36: RP | H36: 2.1 Deliverable A | I36: 200 | J36: PDF | K36: S3 | L36: Shared | M36: 1 | N36: 2 | O36: =IF(Programme!$C$4="","",EOMONTH(Programme!$C$4,2)) | Q36: =IF(AND(O36<>"",P36<>""),P36-O36,"") | R36: Information Manager | S36: TIDP-Z | T36: Y | U36: N | V36: N | X36: Comments closed before the gate
A37: Z-114 | B37: Information Management | D37: ZZ | E37: Baseline model-health report | F37: Report | G37: RP | H37: 2.1 Deliverable A | I37: 200 | J37: PDF | K37: S2 | L37: Shared | M37: 1 | N37: 1 | O37: =IF(Programme!$C$4="","",EOMONTH(Programme!$C$4,1)) | Q37: =IF(AND(O37<>"",P37<>""),P37-O37,"") | R37: Information Manager | S37: TIDP-Z | T37: N | U37: N | V37: N
A38: A-200 | B38: Architecture | D38: ZZ | E38: Architectural model | F38: Model | G38: M3 | H38: 2.2 Deliverable B | I38: 300 | J38: RVT/IFC | K38: S2 | L38: Shared | M38: 2 | N38: 4 | O38: =IF(Programme!$C$4="","",EOMONTH(Programme!$C$4,4)) | Q38: =IF(AND(O38<>"",P38<>""),P38-O38,"") | R38: Architecture lead | S38: TIDP-A | T38: Y | U38: Y | V38: N | X38: Real geometry, correctly located; no placeholder families
A39: A-201 | B39: Architecture | D39: ZZ | E39: General arrangement plans, sections and elevations (50%) | F39: Drawing | G39: DR | H39: 2.2 Deliverable B | I39: 300 | J39: PDF/DWG | K39: S2 | L39: Shared | M39: 4 | N39: 4 | O39: =IF(Programme!$C$4="","",EOMONTH(Programme!$C$4,4)) | Q39: =IF(AND(O39<>"",P39<>""),P39-O39,"") | R39: Architecture lead | S39: TIDP-A | T39: N | U39: Y | V39: N
A40: A-202 | B40: Architecture | D40: ZZ | E40: Door and window schedules | F40: Schedule | G40: SH | H40: 2.2 Deliverable B | I40: 300 | J40: PDF/XLSX | K40: S2 | L40: Shared | M40: 4 | N40: 4 | O40: =IF(Programme!$C$4="","",EOMONTH(Programme!$C$4,4)) | Q40: =IF(AND(O40<>"",P40<>""),P40-O40,"") | R40: Architecture lead | S40: TIDP-A | T40: N | U40: N | V40: N
...

Sheet TIDP-Z
A1: < Cover
B2: Task Information Delivery Plan — Information Management
B4: The deliverables below are those already assigned to you in the Master Information Delivery Plan. Confirm the planned dates, add any deliverable your scope requires that is not listed, and return this sheet to the Information Manager. Rows are merged back into the register by reference. Use the drop-down lists; if a value you need is not offered, raise it rather than typing a variant.
B7: Task Information Delivery Plan | C7: TIDP-Z
B8: Scope | C8: Information Management
B9: Appointed party | C9: Symbion Consulting Group Studios — Information Manager
B10: Originator code | C10: [FILL — once the register is issued]
B11: Task Team Manager | C11: [FILL]
B12: Contact | C12: [FILL]
B13: Revision | C13: P01
B14: Date | C14: [FILL]
B16: Ref | C16: Discipline | D16: Originator | E16: Volume | F16: Deliverable | G16: Type | H16: Type code | I16: Stage | J16: LOD | K16: Format | L16: Suitability | M16: CDE State | N16: Month from | O16: Month to | P16: Planned date | Q16: Actual date | R16: Variance (days) | S16: Responsible | T16: TIDP ref | U16: Critical | V16: As-built | W16: O&M | X16: RAG | Y16: Notes
B17: Z-000 | C17: Information Management | E17: ZZ | F17: BIM Execution Plan | G17: Document | H17: RP | I17: Mobilisation | J17: n/a | K17: DOCX/PDF | L17: A1 | M17: Published | N17: 0 | O17: 0 | S17: Information Manager | T17: TIDP-Z | U17: N | V17: N | W17: N | Y17: Baselined at mobilisation; reissued per stage
B18: Z-001 | C18: Information Management | E18: ZZ | F18: Master Information Delivery Plan | G18: Schedule | H18: SH | I18: Mobilisation | J18: n/a | K18: XLSX | L18: A1 | M18: Published | N18: 0 | O18: 0 | S18: Information Manager | T18: TIDP-Z | U18: N | V18: N | W18: N | Y18: Aggregated from all TIDPs; monthly and per drop
B19: Z-002 | C19: Information Management | E19: ZZ | F19: Project Delivery Playbook | G19: Document | H19: RP | I19: Mobilisation | J19: n/a | K19: DOCX/PDF | L19: A1 | M19: Published | N19: 0 | O19: 0 | S19: Information Manager | T19: TIDP-Z | U19: N | V19: N | W19: N | Y19: Reference RP-Z-0002
B20: Z-003 | C20: Information Management | E20: ZZ | F20: Responsibility matrix (RACI) | G20: Schedule | H20: SH | I20: Mobilisation | J20: n/a | K20: XLSX | L20: A1 | M20: Published | N20: 0 | O20: 0 | S20: Information Manager | T20: TIDP-Z | U20: N | V20: N | W20: N | Y20: Reference SH-Z-0002
B21: Z-004 | C21: Information Management | E21: ZZ | F21: Project template, family library and title blocks | G21: Model | H21: M3 | I21: Mobilisation | J21: n/a | K21: RVT/RFA | L21: A1 | M21: Published | N21: 0 | O21: 0 | S21: Information Manager | T21: TIDP-Z | U21: Y | V21: N | W21: N | Y21: Coordinates, levels, grids, worksets, shared parameters bound
B22: Z-005 | C22: Information Management | E22: ZZ | F22: Originator code register | G22: Schedule | H22: SH | I22: Mobilisation | J22: n/a | K22: XLSX | L22: A1 | M22: Published | N22: 0 | O22: 0 | S22: Lead Appointed Party | T22: TIDP-Z | U22: Y | V22: N | W22: N | Y22: Required before any container is numbered; 3-character codes
B23: Z-007 | C23: Information Management | E23: ZZ | F23: Standards reconciliation schedule (BEP 4.1.3) | G23: Schedule | H23: SH | I23: Mobilisation | J23: n/a | K23: XLSX/PDF | L23: S3 | M23: Shared | N23: 0 | O23: 8 | S23: All disciplines | T23: TIDP-Z | U23: Y | V23: N | W23: N | Y23: Opened at mobilisation; closed before Stage 2.3
B24: Z-008 | C24: Information Management | E24: ZZ | F24: Shared coordinates seed model | G24: Model | H24: M3 | I24: Mobilisation | J24: n/a | K24: RVT | L24: A1 | M24: Published | N24: 0 | O24: 0 | S24: Information Manager | T24: TIDP-Z | U24: Y | V24: N | W24: N | Y24: Survey point, project base point, true north, levels and grids
B25: Z-009 | C25: Information Management | E25: ZZ | F25: Level and grid register | G25: Schedule | H25: SH | I25: Mobilisation | J25: n/a | K25: XLSX/PDF | L25: A1 | M25: Published | N25: 0 | O25: 0 | S25: Lead Appointed Party | T25: TIDP-Z | U25: Y | V25: N | W25: N | Y25: Reference SH-Z-0003
B26: Z-011 | C26: Information Management | E26: ZZ | F26: Software and version register | G26: Schedule | H26: SH | I26: Mobilisation | J26: n/a | K26: XLSX | L26: A1 | M26: Published | N26: 0 | O26: 0 | S26: All parties | T26: TIDP-Z | U26: N | V26: N | W26: N | Y26: Revit 2025 locked project-wide
B27: Z-012 | C27: Information Management | E27: ZZ | F27: CDE folder structure and permission matrix | G27: Document | H27: RP | I27: Mobilisation | J27: n/a | K27: PDF | L27: A1 | M27: Published | N27: 0 | O27: 0 | S27: Information Manager | T27: TIDP-Z | U27: N | V27: N | W27: N | Y27: ACC provisioned; seats confirmed for every party (E-01)
B28: Z-013 | C28: Information Management | E28: ZZ | F28: Information classification and access schedule | G28: Document | H28: RP | I28: Mobilisation | J28: n/a | K28: PDF | L28: A1 | M28: Published | N28: 0 | O28: 0 | S28: Appointing Party | T28: TIDP-Z | U28: Y | V28: N | W28: N | Y28: Restricted spaces and systems classified before modelling begins
... B37: Z-022 | C37: Information Management | E37: ZZ | F37: Document Control Standard (reissued to P02 codes) | G37: Document | H37: RP | I37: Mobilisation | J37: n/a | K37: DOCX/PDF | L37: A1 | M37: Published | N37: 0 | O37: 0 | S37: Information Manager | T37: TIDP-Z | U37: N | V37: N | W37: N | Y37: KUT-SMB-ZZ-ZZ-RP-Z-0003. Container naming, sheet number bands, revision, authorisation, transmittal, superseded/cancelled/replaced notices, number retirement
B38: Z-024 | C38: Information Management | E38: ZZ | F38: Drawing register, transmittal and notice templates | G38: Document | H38: IE | I38: Mobilisation | J38: n/a | K38: XLSX/DOCX | L38: A1 | M38: Published | N38: 0 | O38: 0 | S38: Information Manager | T38: TIDP-Z | U38: N | V38: N | W38: N
B39: Z-010 | C39: Information Management | E39: ZZ | F39: Federated coordination model | G39: Model | H39: M3 | I39: 2.1 Deliverable A | J39: 200 | K39: NWC/NWD/IFC | L39: S1 | M39: Shared | N39: 1 | O39: 1 | S39: Information Manager | T39: TIDP-Z | U39: Y | V39: Y | W39: N | Y39: First federation; container M3-Z-0001
B40: Z-110 | C40: Information Management | E40: ZZ | F40: Basis of design report | G40: Document | H40: RP | I40: 2.1 Deliverable A | J40: 200 | K40: DOCX/PDF | L40: S3 | M40: Shared | N40: 1 | O40: 1 | S40: Lead Appointed Party | T40: TIDP-Z | U40: N | V40: N | W40: N | Y40: Design intent
B41: Z-111 | C41: Information Management | E41: ZZ | F41: Area schedule reconciled to the brief | G41: Schedule | H41: SH | I41: 2.1 Deliverable A | J41: 200 | K41: XLSX/PDF | L41: S3 | M41: Shared | N41: 1 | O41: 1 | S41: Information Manager | T41: TIDP-Z | U41: N | V41: N | W41: N | Y41: Gate condition
B42: Z-112 | C42: Information Management | E42: ZZ | F42: Deliverable A gate pack and compliance report | G42: Document | H42: RP | I42: 2.1 Deliverable A | J42: 200 | K42: PDF | L42: S4 | M42: Shared | N42: 1 | O42: 1 | S42: Information Manager | T42: TIDP-Z | U42: Y | V42: N | W42: N | Y42: Contents per Playbook Appendix B
B43: Z-113 | C43: Information Management | E43: ZZ | F43: Deliverable A Owner review set and comment close-out report | G43: Document | H43: RP | I43: 2.1 Deliverable A | J43: 200 | K43: PDF | L43: S3 | M43: Shared | N43: 1 | O43: 2 | S43: Information Manager | T43: TIDP-Z | U43: Y | V43: N | W43: N | Y43: Comments closed before the gate
B44: Z-114 | C44: Information Management | E44: ZZ | F44: Baseline model-health report | G44: Report | H44: RP | I44: 2.1 Deliverable A | J44: 200 | K44: PDF | L44: S2 | M44: Shared | N44: 1 | O44: 1 | S44: Information Manager | T44: TIDP-Z | U44: N | V44: N | W44: N
B45: Z-210 | C45: Information Management | E45: ZZ | F45: Coordination reports (fortnightly) and Deliverable B clash close-out | G45: Report | H45: CR | I45: 2.2 Deliverable B | J45: 300 | K45: PDF/BCF | L45: S2 | M45: Shared | N45: 2 | O45: 4 | S45: Information Manager | T45: TIDP-Z | U45: N | V45: N | W45: N | Y45: No unresolved high-priority clashes at the gate
B46: Z-211 | C46: Information Management | E46: ZZ | F46: Federated model | G46: Model | H46: M3 | I46: 2.2 Deliverable B | J46: 300 | K46: NWC/NWD/IFC | L46: S2 | M46: Shared | N46: 4 | O46: 4 | S46: Information Manager | T46: TIDP-Z | U46: Y | V46: Y | W46: N | Y46: Milestone NWD archived
B47: Z-213 | C47: Information Management | E47: ZZ | F47: Deliverable B gate pack, LOD 300 verification and compliance report | G47: Document | H47: RP | I47: 2.2 Deliverable B | J47: 300 | K47: PDF | L47: S4 | M47: Shared | N47: 4 | O47: 4 | S47: Information Manager | T47: TIDP-Z | U47: Y | V47: N | W47: N
B48: Z-214 | C48: Information Management | E48: ZZ | F48: Deliverable B Owner review set and comment close-out report | G48: Document | H48: RP | I48: 2.2 Deliverable B | J48: 300 | K48: PDF | L48: S3 | M48: Shared | N48: 4 | O48: 5 | S48: Information Manager | T48: TIDP-Z | U48: Y | V48: N | W48: N
B49: Z-312 | C49: Information Management | E49: ZZ | F49: Specification reconciliation report (model vs SpecLink) | G49: Report | H49: RP | I49: 2.3 Deliverable C | J49: 350 | K49: XLSX/PDF | L49: S4 | M49: Shared | N49: 8 | O49: 8 | S49: Information Manager | T49: TIDP-Z | U49: N | V49: N | W49: N | Y49: Gaps closed or formally accepted
B50: Z-313 | C50: Information Management | E50: ZZ | F50: Deliverable C gate pack, LOD 350 verification and compliance report | G50: Document | H50: RP | I50: 2.3 Deliverable C | J50: 350 | K50: PDF | L50: S4 | M50: Shared | N50: 8 | O50: 8 | S50: Information Manager | T50: TIDP-Z | U50: Y | V50: N | W50: N | Y50: Includes FF&E currency report
B51: Z-314 | C51: Information Management | E51: ZZ | F51: Deliverable C Owner review set and comment close-out report | G51: Document | H51: RP | I51: 2.3 Deliverable C | J51: 350 | K51: PDF | L51: S3 | M51: Shared | N51: 8 | O51: 9 | S51: Information Manager | T51: TIDP-Z | U51: Y | V51: N | W51: N
B52: Z-400 | C52: Information Management | E52: ZZ | F52: Tender documents | G52: Document | H52: RP | I52: 2.4 Tender | J52: n/a | K52: PDF | L52: A1 | M52: Published | N52: 9 | O52: 9 | S52: Lead Appointed Party | T52: TIDP-Z | U52: N | V52: N | W52: N | Y52: Issued from the CDE at A1
...

Sheet TIDP-A
A1: < Cover
B2: Task Information Delivery Plan — Architecture and interiors
B4: The deliverables below are those already assigned to you in the Master Information Delivery Plan. Confirm the planned dates, add any deliverable your scope requires that is not listed, and return this sheet to the Information Manager. Rows are merged back into the register by reference. Use the drop-down lists; if a value you need is not offered, raise it rather than typing a variant.
B7: Task Information Delivery Plan | C7: TIDP-A
B8: Scope | C8: Architecture and interiors
B9: Appointed party | C9: [FILL — architecture practice]
B10: Originator code | C10: [FILL — once the register is issued]
B11: Task Team Manager | C11: [FILL]
B12: Contact | C12: [FILL]
B13: Revision | C13: P01
B14: Date | C14: [FILL]
B16: Ref | C16: Discipline | D16: Originator | E16: Volume | F16: Deliverable | G16: Type | H16: Type code | I16: Stage | J16: LOD | K16: Format | L16: Suitability | M16: CDE State | N16: Month from | O16: Month to | P16: Planned date | Q16: Actual date | R16: Variance (days) | S16: Responsible | T16: TIDP ref | U16: Critical | V16: As-built | W16: O&M | X16: RAG | Y16: Notes
B17: A-100 | C17: Architecture | E17: ZZ | F17: Architectural model | G17: Model | H17: M3 | I17: 2.1 Deliverable A | J17: 200 | K17: RVT/IFC | L17: S2 | M17: Shared | N17: 1 | O17: 1 | S17: Architecture lead | T17: TIDP-A | U17: Y | V17: Y | W17: N | Y17: Massing and generic systems; rooms placed
B18: A-101 | C18: Architecture | E18: ZZ | F18: Deliverable A drawing set | G18: Drawing | H18: DR | I18: 2.1 Deliverable A | J18: 200 | K18: PDF/DWG | L18: S3 | M18: Shared | N18: 1 | O18: 1 | S18: Architecture lead | T18: TIDP-A | U18: N | V18: N | W18: N
B19: A-200 | C19: Architecture | E19: ZZ | F19: Architectural model | G19: Model | H19: M3 | I19: 2.2 Deliverable B | J19: 300 | K19: RVT/IFC | L19: S2 | M19: Shared | N19: 2 | O19: 4 | S19: Architecture lead | T19: TIDP-A | U19: Y | V19: Y | W19: N | Y19: Real geometry, correctly located; no placeholder families
B20: A-201 | C20: Architecture | E20: ZZ | F20: General arrangement plans, sections and elevations (50%) | G20: Drawing | H20: DR | I20: 2.2 Deliverable B | J20: 300 | K20: PDF/DWG | L20: S2 | M20: Shared | N20: 4 | O20: 4 | S20: Architecture lead | T20: TIDP-A | U20: N | V20: Y | W20: N
B21: A-202 | C21: Architecture | E21: ZZ | F21: Door and window schedules | G21: Schedule | H21: SH | I21: 2.2 Deliverable B | J21: 300 | K21: PDF/XLSX | L21: S2 | M21: Shared | N21: 4 | O21: 4 | S21: Architecture lead | T21: TIDP-A | U21: N | V21: N | W21: N
B22: A-203 | C22: Architecture | E22: ZZ | F22: Room data sheets (key spaces) | G22: Room data sheet | H22: RD | I22: 2.2 Deliverable B | J22: 300 | K22: PDF | L22: S2 | M22: Shared | N22: 4 | O22: 4 | S22: Architecture lead | T22: TIDP-A | U22: N | V22: N | W22: N | Y22: Complete set at Deliverable C (A-302)
B23: A-204 | C23: Architecture | E23: ZZ | F23: Existing conditions and removals plan | G23: Drawing | H23: DR | I23: 2.2 Deliverable B | J23: 300 | K23: PDF/DWG | L23: S2 | M23: Shared | N23: 4 | O23: 4 | S23: Architecture lead | T23: TIDP-A | U23: N | V23: N | W23: N | Y23: Demolition classification is a manual task; BEP 10.4
B24: A-300 | C24: Architecture | E24: ZZ | F24: Architectural model | G24: Model | H24: M3 | I24: 2.3 Deliverable C | J24: 350 | K24: RVT/IFC | L24: S4 | M24: Shared | N24: 5 | O24: 8 | S24: Architecture lead | T24: TIDP-A | U24: Y | V24: Y | W24: N | Y24: Interfaces resolved
B25: A-301 | C25: Architecture | E25: ZZ | F25: Full drawing set (100%) and details | G25: Drawing | H25: DR | I25: 2.3 Deliverable C | J25: 350 | K25: PDF/DWG | L25: S4 | M25: Shared | N25: 8 | O25: 8 | S25: Architecture lead | T25: TIDP-A | U25: Y | V25: Y | W25: N
B26: A-302 | C26: Architecture | E26: ZZ | F26: Room data sheets (complete) | G26: Room data sheet | H26: RD | I26: 2.3 Deliverable C | J26: 350 | K26: PDF | L26: S4 | M26: Shared | N26: 8 | O26: 8 | S26: Architecture lead | T26: TIDP-A | U26: N | V26: N | W26: N | Y26: Generated from the reconciled Fohlio data
B27: A-500 | C27: Architecture | E27: ZZ | F27: Construction-stage model (revisions tracked) | G27: Model | H27: M3 | I27: 3.1 Construction | J27: 400 | K27: RVT/IFC | L27: A1 | M27: Published | N27: 12 | O27: 43 | S27: Architecture lead | T27: TIDP-A | U27: Y | V27: Y | W27: N
B28: A-700 | C28: Architecture | E28: ZZ | F28: As-built architectural model (LOD 500, verified) | G28: Model | H28: M3 | I28: 3.3 Deliverable D | J28: 500 | K28: RVT/IFC | L28: A1 | M28: Published | N28: 48 | O28: 49 | S28: Architecture lead | T28: TIDP-A | U28: Y | V28: Y | W28: Y | Y28: Authored by the design consultant from the Contractor as-built documentation; verified by the Information Manager

Sheet TIDP-S
A1: < Cover
B2: Task Information Delivery Plan — Structural
B4: The deliverables below are those already assigned to you in the Master Information Delivery Plan. Confirm the planned dates, add any deliverable your scope requires that is not listed, and return this sheet to the Information Manager. Rows are merged back into the register by reference. Use the drop-down lists; if a value you need is not offered, raise it rather than typing a variant.
B7: Task Information Delivery Plan | C7: TIDP-S
B8: Scope | C8: Structural
B9: Appointed party | C9: [FILL — structural engineer]
B10: Originator code | C10: [FILL — once the register is issued]
B11: Task Team Manager | C11: [FILL]
B12: Contact | C12: [FILL]
B13: Revision | C13: P01
B14: Date | C14: [FILL]
B16: Ref | C16: Discipline | D16: Originator | E16: Volume | F16: Deliverable | G16: Type | H16: Type code | I16: Stage | J16: LOD | K16: Format | L16: Suitability | M16: CDE State | N16: Month from | O16: Month to | P16: Planned date | Q16: Actual date | R16: Variance (days) | S16: Responsible | T16: TIDP ref | U16: Critical | V16: As-built | W16: O&M | X16: RAG | Y16: Notes
B17: S-100 | C17: Structure | E17: ZZ | F17: Structural model | G17: Model | H17: M3 | I17: 2.1 Deliverable A | J17: 200 | K17: RVT/IFC | L17: S2 | M17: Shared | N17: 1 | O17: 1 | S17: Structural lead | T17: TIDP-S | U17: Y | V17: Y | W17: N | Y17: Indicative frame and foundations
B18: S-200 | C18: Structure | E18: ZZ | F18: Structural model | G18: Model | H18: M3 | I18: 2.2 Deliverable B | J18: 300 | K18: RVT/IFC | L18: S2 | M18: Shared | N18: 2 | O18: 4 | S18: Structural lead | T18: TIDP-S | U18: Y | V18: Y | W18: N | Y18: Sized members; penetrations coordinated
B19: S-201 | C19: Structure | E19: ZZ | F19: General arrangement drawings (50%) | G19: Drawing | H19: DR | I19: 2.2 Deliverable B | J19: 300 | K19: PDF/DWG | L19: S2 | M19: Shared | N19: 4 | O19: 4 | S19: Structural lead | T19: TIDP-S | U19: N | V19: Y | W19: N
B20: S-300 | C20: Structure | E20: ZZ | F20: Structural model | G20: Model | H20: M3 | I20: 2.3 Deliverable C | J20: 350 | K20: RVT/IFC | L20: S4 | M20: Shared | N20: 5 | O20: 8 | S20: Structural lead | T20: TIDP-S | U20: Y | V20: Y | W20: N | Y20: Connections resolved
B21: S-301 | C21: Structure | E21: ZZ | F21: Structural drawing set (100%) | G21: Drawing | H21: DR | I21: 2.3 Deliverable C | J21: 350 | K21: PDF/DWG | L21: S4 | M21: Shared | N21: 8 | O21: 8 | S21: Structural lead | T21: TIDP-S | U21: Y | V21: Y | W21: N
B22: S-500 | C22: Structure | E22: ZZ | F22: Construction-stage model (revisions tracked) | G22: Model | H22: M3 | I22: 3.1 Construction | J22: 400 | K22: RVT/IFC | L22: A1 | M22: Published | N22: 12 | O22: 43 | S22: Structural lead | T22: TIDP-S | U22: Y | V22: Y | W22: N
B23: S-700 | C23: Structure | E23: ZZ | F23: As-built structural model (LOD 500, verified) | G23: Model | H23: M3 | I23: 3.3 Deliverable D | J23: 500 | K23: RVT/IFC | L23: A1 | M23: Published | N23: 48 | O23: 49 | S23: Structural lead | T23: TIDP-S | U23: Y | V23: Y | W23: Y | Y23: Authored by the design consultant from the Contractor as-built documentation; verified by the Information Manager

Sheet TIDP-M
A1: < Cover
B2: Task Information Delivery Plan — Mechanical
B4: The deliverables below are those already assigned to you in the Master Information Delivery Plan. Confirm the planned dates, add any deliverable your scope requires that is not listed, and return this sheet to the Information Manager. Rows are merged back into the register by reference. Use the drop-down lists; if a value you need is not offered, raise it rather than typing a variant.
B7: Task Information Delivery Plan | C7: TIDP-M
B8: Scope | C8: Mechanical
B9: Appointed party | C9: [FILL — MEP engineer]
B10: Originator code | C10: [FILL — once the register is issued]
B11: Task Team Manager | C11: [FILL]
B12: Contact | C12: [FILL]
B13: Revision | C13: P01
B14: Date | C14: [FILL]
B16: Ref | C16: Discipline | D16: Originator | E16: Volume | F16: Deliverable | G16: Type | H16: Type code | I16: Stage | J16: LOD | K16: Format | L16: Suitability | M16: CDE State | N16: Month from | O16: Month to | P16: Planned date | Q16: Actual date | R16: Variance (days) | S16: Responsible | T16: TIDP ref | U16: Critical | V16: As-built | W16: O&M | X16: RAG | Y16: Notes
B17: M-100 | C17: Mechanical | E17: ZZ | F17: Mechanical model | G17: Model | H17: M3 | I17: 2.1 Deliverable A | J17: 200 | K17: RVT/IFC | L17: S2 | M17: Shared | N17: 1 | O17: 1 | S17: MEP lead | T17: TIDP-M | U17: Y | V17: Y | W17: N | Y17: Plant space allocation, primary routes
B18: M-200 | C18: Mechanical | E18: ZZ | F18: Mechanical model | G18: Model | H18: M3 | I18: 2.2 Deliverable B | J18: 300 | K18: RVT/IFC | L18: S2 | M18: Shared | N18: 2 | O18: 4 | S18: MEP lead | T18: TIDP-M | U18: Y | V18: Y | W18: N | Y18: Real equipment; risers fixed
B19: M-201 | C19: Mechanical | E19: ZZ | F19: HVAC layouts (50%) | G19: Drawing | H19: DR | I19: 2.2 Deliverable B | J19: 300 | K19: PDF/DWG | L19: S2 | M19: Shared | N19: 4 | O19: 4 | S19: MEP lead | T19: TIDP-M | U19: N | V19: Y | W19: N
B20: M-300 | C20: Mechanical | E20: ZZ | F20: Mechanical model | G20: Model | H20: M3 | I20: 2.3 Deliverable C | J20: 350 | K20: RVT/IFC | L20: S4 | M20: Shared | N20: 5 | O20: 8 | S20: MEP lead | T20: TIDP-M | U20: Y | V20: Y | W20: N | Y20: Systems complete and connected; equipment data
B21: M-301 | C21: Mechanical | E21: ZZ | F21: HVAC drawing set (100%) | G21: Drawing | H21: DR | I21: 2.3 Deliverable C | J21: 350 | K21: PDF/DWG | L21: S4 | M21: Shared | N21: 8 | O21: 8 | S21: MEP lead | T21: TIDP-M | U21: Y | V21: Y | W21: N
B22: M-302 | C22: Mechanical | E22: ZZ | F22: HVAC load and sizing schedules | G22: Schedule | H22: SH | I22: 2.3 Deliverable C | J22: 350 | K22: PDF/XLSX | L22: S4 | M22: Shared | N22: 8 | O22: 8 | S22: MEP lead | T22: TIDP-M | U22: Y | V22: N | W22: N
B23: M-303 | C23: Mechanical | E23: ZZ | F23: BMS point-naming convention and point data on serviceable elements | G23: Schedule | H23: SH | I23: 2.3 Deliverable C | J23: 350 | K23: XLSX | L23: S3 | M23: Shared | N23: 8 | O23: 8 | S23: MEP lead | T23: TIDP-M | U23: N | V23: N | W23: N | Y23: Agreed with the controls contractor
B24: M-500 | C24: Mechanical | E24: ZZ | F24: Construction-stage model (revisions tracked) | G24: Model | H24: M3 | I24: 3.1 Construction | J24: 400 | K24: RVT/IFC | L24: A1 | M24: Published | N24: 12 | O24: 43 | S24: MEP lead | T24: TIDP-M | U24: Y | V24: Y | W24: N | Y24: Maintenance type on plumbing fixtures from LOD 400
B25: M-520 | C25: Mechanical | E25: ZZ | F25: Commissioning point list (Niagara) | G25: Schedule | H25: SH | I25: 3.1 Construction | J25: 400 | K25: CSV | L25: S2 | M25: Shared | N25: 40 | O25: 40 | S25: MEP lead | T25: TIDP-M | U25: Y | V25: N | W25: Y | Y25: Produced from the model for the controls contractor
B26: M-700 | C26: Mechanical | E26: ZZ | F26: As-built mechanical model (LOD 500, verified) | G26: Model | H26: M3 | I26: 3.3 Deliverable D | J26: 500 | K26: RVT/IFC | L26: A1 | M26: Published | N26: 48 | O26: 49 | S26: MEP lead | T26: TIDP-M | U26: Y | V26: Y | W26: Y | Y26: Authored by the design consultant from the Contractor as-built documentation; verified by the Information Manager

Sheet TIDP-E
A1: < Cover
B2: Task Information Delivery Plan — Electrical
B4: The deliverables below are those already assigned to you in the Master Information Delivery Plan. Confirm the planned dates, add any deliverable your scope requires that is not listed, and return this sheet to the Information Manager. Rows are merged back into the register by reference. Use the drop-down lists; if a value you need is not offered, raise it rather than typing a variant.
B7: Task Information Delivery Plan | C7: TIDP-E
B8: Scope | C8: Electrical
B9: Appointed party | C9: [FILL — MEP engineer]
B10: Originator code | C10: [FILL — once the register is issued]
B11: Task Team Manager | C11: [FILL]
B12: Contact | C12: [FILL]
B13: Revision | C13: P01
B14: Date | C14: [FILL]
B16: Ref | C16: Discipline | D16: Originator | E16: Volume | F16: Deliverable | G16: Type | H16: Type code | I16: Stage | J16: LOD | K16: Format | L16: Suitability | M16: CDE State | N16: Month from | O16: Month to | P16: Planned date | Q16: Actual date | R16: Variance (days) | S16: Responsible | T16: TIDP ref | U16: Critical | V16: As-built | W16: O&M | X16: RAG | Y16: Notes
B17: E-100 | C17: Electrical | E17: ZZ | F17: Electrical model | G17: Model | H17: M3 | I17: 2.1 Deliverable A | J17: 200 | K17: RVT/IFC | L17: S2 | M17: Shared | N17: 1 | O17: 1 | S17: MEP lead | T17: TIDP-E | U17: Y | V17: Y | W17: N | Y17: Generic equipment and main containment
B18: E-200 | C18: Electrical | E18: ZZ | F18: Electrical model | G18: Model | H18: M3 | I18: 2.2 Deliverable B | J18: 300 | K18: RVT/IFC | L18: S2 | M18: Shared | N18: 2 | O18: 4 | S18: MEP lead | T18: TIDP-E | U18: Y | V18: Y | W18: N | Y18: Power, lighting and containment routed; boards placed
B19: E-201 | C19: Electrical | E19: ZZ | F19: Power and lighting layouts (50%) | G19: Drawing | H19: DR | I19: 2.2 Deliverable B | J19: 300 | K19: PDF/DWG | L19: S2 | M19: Shared | N19: 4 | O19: 4 | S19: MEP lead | T19: TIDP-E | U19: N | V19: Y | W19: N | Y19: Lighting layouts under role E (G-03)
B20: E-300 | C20: Electrical | E20: ZZ | F20: Electrical model and drawing set (100%) | G20: Model/Drawing | H20: M3 | I20: 2.3 Deliverable C | J20: 350 | K20: RVT/PDF | L20: S4 | M20: Shared | N20: 5 | O20: 8 | S20: MEP lead | T20: TIDP-E | U20: Y | V20: Y | W20: N
B21: E-301 | C21: Electrical | E21: ZZ | F21: Panel schedules and single-line diagrams | G21: Schedule/Drawing | H21: DR | I21: 2.3 Deliverable C | J21: 350 | K21: PDF/XLSX | L21: S4 | M21: Shared | N21: 8 | O21: 8 | S21: MEP lead | T21: TIDP-E | U21: Y | V21: Y | W21: N | Y21: Sheets in the 6xxx and 7xxx bands
B22: E-500 | C22: Electrical | E22: ZZ | F22: Construction-stage model (revisions tracked) | G22: Model | H22: M3 | I22: 3.1 Construction | J22: 400 | K22: RVT/IFC | L22: A1 | M22: Published | N22: 12 | O22: 43 | S22: MEP lead | T22: TIDP-E | U22: Y | V22: Y | W22: N
B23: E-700 | C23: Electrical | E23: ZZ | F23: As-built electrical model (LOD 500, verified) | G23: Model | H23: M3 | I23: 3.3 Deliverable D | J23: 500 | K23: RVT/IFC | L23: A1 | M23: Published | N23: 48 | O23: 49 | S23: MEP lead | T23: TIDP-E | U23: Y | V23: Y | W23: Y | Y23: Authored by the design consultant from the Contractor as-built documentation; verified by the Information Manager

Sheet TIDP-P
A1: < Cover
B2: Task Information Delivery Plan — Public health (plumbing and drainage)
B4: The deliverables below are those already assigned to you in the Master Information Delivery Plan. Confirm the planned dates, add any deliverable your scope requires that is not listed, and return this sheet to the Information Manager. Rows are merged back into the register by reference. Use the drop-down lists; if a value you need is not offered, raise it rather than typing a variant.
B7: Task Information Delivery Plan | C7: TIDP-P
B8: Scope | C8: Public health (plumbing and drainage)
B9: Appointed party | C9: [FILL — MEP engineer]
B10: Originator code | C10: [FILL — once the register is issued]
B11: Task Team Manager | C11: [FILL]
B12: Contact | C12: [FILL]
B13: Revision | C13: P01
B14: Date | C14: [FILL]
B16: Ref | C16: Discipline | D16: Originator | E16: Volume | F16: Deliverable | G16: Type | H16: Type code | I16: Stage | J16: LOD | K16: Format | L16: Suitability | M16: CDE State | N16: Month from | O16: Month to | P16: Planned date | Q16: Actual date | R16: Variance (days) | S16: Responsible | T16: TIDP ref | U16: Critical | V16: As-built | W16: O&M | X16: RAG | Y16: Notes
B17: P-100 | C17: Public Health | E17: ZZ | F17: Plumbing and drainage model | G17: Model | H17: M3 | I17: 2.1 Deliverable A | J17: 200 | K17: RVT/IFC | L17: S2 | M17: Shared | N17: 1 | O17: 1 | S17: MEP lead | T17: TIDP-P | U17: Y | V17: Y | W17: N | Y17: Primary routes; font systems indicated
B18: P-200 | C18: Public Health | E18: ZZ | F18: Plumbing and drainage model | G18: Model | H18: M3 | I18: 2.2 Deliverable B | J18: 300 | K18: RVT/IFC | L18: S2 | M18: Shared | N18: 2 | O18: 4 | S18: MEP lead | T18: TIDP-P | U18: Y | V18: Y | W18: N | Y18: Real pipework with code falls; fixtures placed
B19: P-201 | C19: Public Health | E19: ZZ | F19: Plumbing and drainage layouts (50%) | G19: Drawing | H19: DR | I19: 2.2 Deliverable B | J19: 300 | K19: PDF/DWG | L19: S2 | M19: Shared | N19: 4 | O19: 4 | S19: MEP lead | T19: TIDP-P | U19: N | V19: Y | W19: N
B20: P-300 | C20: Public Health | E20: ZZ | F20: Plumbing model and drawing set (100%) | G20: Model/Drawing | H20: M3 | I20: 2.3 Deliverable C | J20: 350 | K20: RVT/PDF | L20: S4 | M20: Shared | N20: 5 | O20: 8 | S20: MEP lead | T20: TIDP-P | U20: Y | V20: Y | W20: N
B21: P-500 | C21: Public Health | E21: ZZ | F21: Construction-stage model (revisions tracked) | G21: Model | H21: M3 | I21: 3.1 Construction | J21: 400 | K21: RVT/IFC | L21: A1 | M21: Published | N21: 12 | O21: 43 | S21: MEP lead | T21: TIDP-P | U21: Y | V21: Y | W21: N
B22: P-700 | C22: Public Health | E22: ZZ | F22: As-built plumbing and drainage model (LOD 500, verified) | G22: Model | H22: M3 | I22: 3.3 Deliverable D | J22: 500 | K22: RVT/IFC | L22: A1 | M22: Published | N22: 48 | O22: 49 | S22: MEP lead | T22: TIDP-P | U22: Y | V22: Y | W22: Y | Y22: Authored by the design consultant from the Contractor as-built documentation; verified by the Information Manager

Sheet TIDP-Y-FP
A1: < Cover
B2: Task Information Delivery Plan — Fire protection
B4: The deliverables below are those already assigned to you in the Master Information Delivery Plan. Confirm the planned dates, add any deliverable your scope requires that is not listed, and return this sheet to the Information Manager. Rows are merged back into the register by reference. Use the drop-down lists; if a value you need is not offered, raise it rather than typing a variant.
B7: Task Information Delivery Plan | C7: TIDP-Y-FP
B8: Scope | C8: Fire protection
B9: Appointed party | C9: [FILL — fire engineer / design-build contractor]
B10: Originator code | C10: [FILL — once the register is issued]
B11: Task Team Manager | C11: [FILL]
B12: Contact | C12: [FILL]
B13: Revision | C13: P01
B14: Date | C14: [FILL]
B16: Ref | C16: Discipline | D16: Originator | E16: Volume | F16: Deliverable | G16: Type | H16: Type code | I16: Stage | J16: LOD | K16: Format | L16: Suitability | M16: CDE State | N16: Month from | O16: Month to | P16: Planned date | Q16: Actual date | R16: Variance (days) | S16: Responsible | T16: TIDP ref | U16: Critical | V16: As-built | W16: O&M | X16: RAG | Y16: Notes
B17: FP-200 | C17: Fire Protection | E17: ZZ | F17: Fire strategy and suppression layout | G17: Model/Document | H17: M3 | I17: 2.2 Deliverable B | J17: 300 | K17: RVT/PDF | L17: S2 | M17: Shared | N17: 2 | O17: 4 | S17: Fire lead | T17: TIDP-Y-FP | U17: Y | V17: Y | W17: N | Y17: Sprinkler and detection layout
B18: FP-300 | C18: Fire Protection | E18: ZZ | F18: Fire strategy and model (100%) | G18: Model/Document | H18: M3 | I18: 2.3 Deliverable C | J18: 350 | K18: RVT/PDF | L18: S4 | M18: Shared | N18: 5 | O18: 8 | S18: Fire lead | T18: TIDP-Y-FP | U18: Y | V18: Y | W18: N | Y18: Transition to the design-build contractor agreed
B19: FP-500 | C19: Fire Protection | E19: ZZ | F19: Construction-stage model (revisions tracked) | G19: Model | H19: M3 | I19: 3.1 Construction | J19: 400 | K19: RVT/IFC | L19: A1 | M19: Published | N19: 12 | O19: 43 | S19: Design-build fire contractor | T19: TIDP-Y-FP | U19: Y | V19: Y | W19: N | Y19: D-B contractor becomes engineer of record
B20: FP-700 | C20: Fire Protection | E20: ZZ | F20: As-built fire protection model (LOD 500, verified) | G20: Model | H20: M3 | I20: 3.3 Deliverable D | J20: 500 | K20: RVT/IFC | L20: A1 | M20: Published | N20: 48 | O20: 49 | S20: Design-build fire contractor | T20: TIDP-Y-FP | U20: Y | V20: Y | W20: Y | Y20: Authored by the design consultant from the Contractor as-built documentation; verified by the Information Manager

Sheet TIDP-Y-LV
A1: < Cover
B2: Task Information Delivery Plan — Low voltage and communications
B4: The deliverables below are those already assigned to you in the Master Information Delivery Plan. Confirm the planned dates, add any deliverable your scope requires that is not listed, and return this sheet to the Information Manager. Rows are merged back into the register by reference. Use the drop-down lists; if a value you need is not offered, raise it rather than typing a variant.
B7: Task Information Delivery Plan | C7: TIDP-Y-LV
B8: Scope | C8: Low voltage and communications
B9: Appointed party | C9: [FILL — LV engineer]
B10: Originator code | C10: [FILL — once the register is issued]
B11: Task Team Manager | C11: [FILL]
B12: Contact | C12: [FILL]
B13: Revision | C13: P01
B14: Date | C14: [FILL]
B16: Ref | C16: Discipline | D16: Originator | E16: Volume | F16: Deliverable | G16: Type | H16: Type code | I16: Stage | J16: LOD | K16: Format | L16: Suitability | M16: CDE State | N16: Month from | O16: Month to | P16: Planned date | Q16: Actual date | R16: Variance (days) | S16: Responsible | T16: TIDP ref | U16: Critical | V16: As-built | W16: O&M | X16: RAG | Y16: Notes
B17: LV-200 | C17: Low Voltage | E17: ZZ | F17: Low voltage containment and equipment rooms | G17: Model | H17: M3 | I17: 2.2 Deliverable B | J17: 300 | K17: RVT/IFC | L17: S2 | M17: Shared | N17: 2 | O17: 4 | S17: LV lead | T17: TIDP-Y-LV | U17: Y | V17: Y | W17: N
B18: LV-300 | C18: Low Voltage | E18: ZZ | F18: Communications and security model and drawings | G18: Model/Drawing | H18: M3 | I18: 2.3 Deliverable C | J18: 350 | K18: RVT/PDF | L18: S4 | M18: Shared | N18: 5 | O18: 8 | S18: LV lead | T18: TIDP-Y-LV | U18: Y | V18: Y | W18: N | Y18: Restricted-information handling per BEP 8.1
B19: LV-500 | C19: Low Voltage | E19: ZZ | F19: Construction-stage model (revisions tracked) | G19: Model | H19: M3 | I19: 3.1 Construction | J19: 400 | K19: RVT/IFC | L19: A1 | M19: Published | N19: 12 | O19: 43 | S19: LV lead | T19: TIDP-Y-LV | U19: Y | V19: Y | W19: N
B20: LV-700 | C20: Low Voltage | E20: ZZ | F20: As-built low voltage model (LOD 500, verified) | G20: Model | H20: M3 | I20: 3.3 Deliverable D | J20: 500 | K20: RVT/IFC | L20: A1 | M20: Published | N20: 48 | O20: 49 | S20: LV lead | T20: TIDP-Y-LV | U20: Y | V20: Y | W20: Y | Y20: Authored by the design consultant from the Contractor as-built documentation; verified by the Information Manager

Sheet TIDP-C
A1: < Cover
B2: Task Information Delivery Plan — Civil and site
B4: The deliverables below are those already assigned to you in the Master Information Delivery Plan. Confirm the planned dates, add any deliverable your scope requires that is not listed, and return this sheet to the Information Manager. Rows are merged back into the register by reference. Use the drop-down lists; if a value you need is not offered, raise it rather than typing a variant.
B7: Task Information Delivery Plan | C7: TIDP-C
B8: Scope | C8: Civil and site
B9: Appointed party | C9: [FILL — civil engineer]
B10: Originator code | C10: [FILL — once the register is issued]
B11: Task Team Manager | C11: [FILL]
B12: Contact | C12: [FILL]
B13: Revision | C13: P01
B14: Date | C14: [FILL]
B16: Ref | C16: Discipline | D16: Originator | E16: Volume | F16: Deliverable | G16: Type | H16: Type code | I16: Stage | J16: LOD | K16: Format | L16: Suitability | M16: CDE State | N16: Month from | O16: Month to | P16: Planned date | Q16: Actual date | R16: Variance (days) | S16: Responsible | T16: TIDP ref | U16: Critical | V16: As-built | W16: O&M | X16: RAG | Y16: Notes
B17: G-100 | C17: Civil and Site | E17: 00 | F17: Site model and levels | G17: Model | H17: M3 | I17: 2.1 Deliverable A | J17: 200 | K17: RVT/IFC | L17: S2 | M17: Shared | N17: 1 | O17: 1 | S17: Civil lead | T17: TIDP-C | U17: Y | V17: Y | W17: N | Y17: Site levels, access, drainage strategy; scope to confirm
B18: G-200 | C18: Civil and Site | E18: 00 | F18: Site model | G18: Model | H18: M3 | I18: 2.2 Deliverable B | J18: 300 | K18: RVT/IFC | L18: S2 | M18: Shared | N18: 2 | O18: 4 | S18: Civil lead | T18: TIDP-C | U18: Y | V18: Y | W18: N | Y18: Real site model; drainage and access
B19: G-201 | C19: Civil and Site | E19: 00 | F19: Site and drainage drawings (50%) | G19: Drawing | H19: DR | I19: 2.2 Deliverable B | J19: 300 | K19: PDF/DWG | L19: S2 | M19: Shared | N19: 4 | O19: 4 | S19: Civil lead | T19: TIDP-C | U19: N | V19: Y | W19: N
B20: G-300 | C20: Civil and Site | E20: 00 | F20: Civil and site model and drawings (100%) | G20: Model/Drawing | H20: M3 | I20: 2.3 Deliverable C | J20: 350 | K20: RVT/PDF | L20: S4 | M20: Shared | N20: 5 | O20: 8 | S20: Civil lead | T20: TIDP-C | U20: Y | V20: Y | W20: N
B21: G-500 | C21: Civil and Site | E21: 00 | F21: Construction-stage model (revisions tracked) | G21: Model | H21: M3 | I21: 3.1 Construction | J21: 400 | K21: RVT/IFC | L21: A1 | M21: Published | N21: 12 | O21: 43 | S21: Civil lead | T21: TIDP-C | U21: Y | V21: Y | W21: N
B22: G-700 | C22: Civil and Site | E22: 00 | F22: As-built civil and site model (LOD 500, verified) | G22: Model | H22: M3 | I22: 3.3 Deliverable D | J22: 500 | K22: RVT/IFC | L22: A1 | M22: Published | N22: 48 | O22: 49 | S22: Civil lead | T22: TIDP-C | U22: Y | V22: Y | W22: Y | Y22: Authored by the design consultant from the Contractor as-built documentation; verified by the Information Manager

Sheet TIDP-Q
A1: < Cover
B2: Task Information Delivery Plan — Quantity surveying / cost
B4: The deliverables below are those already assigned to you in the Master Information Delivery Plan. Confirm the planned dates, add any deliverable your scope requires that is not listed, and return this sheet to the Information Manager. Rows are merged back into the register by reference. Use the drop-down lists; if a value you need is not offered, raise it rather than typing a variant.
B7: Task Information Delivery Plan | C7: TIDP-Q
B8: Scope | C8: Quantity surveying / cost
B9: Appointed party | C9: [FILL — quantity surveyor]
B10: Originator code | C10: [FILL — once the register is issued]
B11: Task Team Manager | C11: [FILL]
B12: Contact | C12: [FILL]
B13: Revision | C13: P01
B14: Date | C14: [FILL]
B16: Ref | C16: Discipline | D16: Originator | E16: Volume | F16: Deliverable | G16: Type | H16: Type code | I16: Stage | J16: LOD | K16: Format | L16: Suitability | M16: CDE State | N16: Month from | O16: Month to | P16: Planned date | Q16: Actual date | R16: Variance (days) | S16: Responsible | T16: TIDP ref | U16: Critical | V16: As-built | W16: O&M | X16: RAG | Y16: Notes
B17: Z-212 | C17: QS / Cost | E17: ZZ | F17: Bill of quantities (preliminary) | G17: Schedule | H17: CP | I17: 2.2 Deliverable B | J17: 300 | K17: XLSX | L17: S2 | M17: Shared | N17: 4 | O17: 4 | S17: Quantity Surveyor | T17: TIDP-Q | U17: Y | V17: N | W17: Y | Y17: Derived from the coordinated models by the QS
B18: Z-310 | C18: QS / Cost | E18: ZZ | F18: Bill of quantities (tender) | G18: Schedule | H18: CP | I18: 2.3 Deliverable C | J18: 350 | K18: XLSX | L18: S4 | M18: Shared | N18: 8 | O18: 8 | S18: Quantity Surveyor | T18: TIDP-Q | U18: Y | V18: N | W18: Y

Sheet TIDP-I
A1: < Cover
B2: Task Information Delivery Plan — FF&E and finishes (Interior Designer)
B4: The deliverables below are those already assigned to you in the Master Information Delivery Plan. Confirm the planned dates, add any deliverable your scope requires that is not listed, and return this sheet to the Information Manager. Rows are merged back into the register by reference. Use the drop-down lists; if a value you need is not offered, raise it rather than typing a variant.
B7: Task Information Delivery Plan | C7: TIDP-I
B8: Scope | C8: FF&E and finishes (Interior Designer)
B9: Appointed party | C9: [FILL — interior designer]
B10: Originator code | C10: [FILL — once the register is issued]
B11: Task Team Manager | C11: [FILL]
B12: Contact | C12: [FILL]
B13: Revision | C13: P01
B14: Date | C14: [FILL]
